Workbook

Sheet Sheet1
A1: Antibiotic | B1: Class | C1: ATC code | D1: AWARE_Cat2025 | E1: Status_EML2025 | F1: AWARE_Cat2021 | G1: Status_EML2021 | H1: AWARE_Cat2019 | I1: Status_EML2019 | J1: EML_2025
A2: Amikacin | B2: Aminoglycosides | C2: J01GB06 | D2: Access | E2: Yes | F2: Access | G2: Yes | H2: =VLOOKUP(C2,Sheet2!A:D,3,0) -> Access | I2: =VLOOKUP(C2,Sheet2!A:D,4,0) -> Yes | J2: Access group antibiotics
A3: Amoxicillin | B3: Penicillins | C3: J01CA04 | D3: Access | E3: Yes | F3: Access | G3: Yes | H3: =VLOOKUP(C3,Sheet2!A:D,3,0) -> Access | I3: =VLOOKUP(C3,Sheet2!A:D,4,0) -> Yes | J3: Access group antibiotics
A4: Amoxicillin/clavulanic-acid | B4: Beta-lactam/beta-lactamase-inhibitor | C4: J01CR02 | D4: Access | E4: Yes | F4: Access | G4: Yes | H4: =VLOOKUP(C4,Sheet2!A:D,3,0) -> Access | I4: =VLOOKUP(C4,Sheet2!A:D,4,0) -> Yes | J4: Access group antibiotics
A5: Amoxicillin/sulbactam | B5: Beta-lactam/beta-lactamase-inhibitor | C5: J01CR02 | D5: Access | E5: No | F5: #N/A | G5: #N/A | H5: =VLOOKUP(C5,Sheet2!A:D,3,0) -> Access | I5: =VLOOKUP(C5,Sheet2!A:D,4,0) -> Yes | J5: Access group antibiotics
A6: Ampicillin | B6: Penicillins | C6: J01CA01 | D6: Access | E6: Yes | F6: Access | G6: Yes | H6: =VLOOKUP(C6,Sheet2!A:D,3,0) -> Access | I6: =VLOOKUP(C6,Sheet2!A:D,4,0) -> Yes | J6: #N/A
A7: Ampicillin/sulbactam | B7: Beta-lactam/beta-lactamase-inhibitor | C7: J01CR01 | D7: Access | E7: No | F7: Access | G7: No | H7: =VLOOKUP(C7,Sheet2!A:D,3,0) -> Access | I7: =VLOOKUP(C7,Sheet2!A:D,4,0) -> No | J7: #N/A
A8: Azanidazole | B8: Imidazoles | C8: P01AB04 | D8: Access | E8: No | F8: #N/A | G8: #N/A | H8: =VLOOKUP(C8,Sheet2!A:D,3,0) -> #N/A | I8: =VLOOKUP(C8,Sheet2!A:D,4,0) -> #N/A | J8: #N/A
A9: Azidocillin | B9: Penicillins | C9: J01CE04 | D9: Access | E9: No | F9: Access | G9: No | H9: =VLOOKUP(C9,Sheet2!A:D,3,0) -> #N/A | I9: =VLOOKUP(C9,Sheet2!A:D,4,0) -> #N/A | J9: #N/A
A10: Bacampicillin | B10: Penicillins | C10: J01CA06 | D10: Access | E10: No | F10: Access | G10: No | H10: =VLOOKUP(C10,Sheet2!A:D,3,0) -> Access | I10: =VLOOKUP(C10,Sheet2!A:D,4,0) -> No | J10: #N/A
A11: Benzathine-benzylpenicillin | B11: Penicillins | C11: J01CE08 | D11: Access | E11: Yes | F11: Access | G11: Yes | H11: =VLOOKUP(C11,Sheet2!A:D,3,0) -> Access | I11: =VLOOKUP(C11,Sheet2!A:D,4,0) -> Yes | J11: Access group antibiotics
A12: Benzathine-phenoxymethylpenicillin | B12: Penicillins | C12: J01CE10 | D12: Access | E12: No | F12: #N/A | G12: #N/A | H12: =VLOOKUP(C12,Sheet2!A:D,3,0) -> #N/A | I12: =VLOOKUP(C12,Sheet2!A:D,4,0) -> #N/A | J12: #N/A
A13: Benzylpenicillin | B13: Penicillins | C13: J01CE01 | D13: Access | E13: Yes | F13: Access | G13: Yes | H13: =VLOOKUP(C13,Sheet2!A:D,3,0) -> Access | I13: =VLOOKUP(C13,Sheet2!A:D,4,0) -> Yes | J13: Access group antibiotics
A14: Brodimoprim | B14: Trimethoprim-derivatives | C14: J01EA02 | D14: Access | E14: No | F14: Access | G14: No | H14: =VLOOKUP(C14,Sheet2!A:D,3,0) -> #N/A | I14: =VLOOKUP(C14,Sheet2!A:D,4,0) -> #N/A | J14: #N/A
A15: Cefacetrile | B15: First-generation-cephalosporins | C15: J01DB10 | D15: Access | E15: No | F15: Access | G15: No | H15: =VLOOKUP(C15,Sheet2!A:D,3,0) -> Access | I15: =VLOOKUP(C15,Sheet2!A:D,4,0) -> No | J15: #N/A
A16: Cefadroxil | B16: First-generation-cephalosporins | C16: J01DB05 | D16: Access | E16: No | F16: Access | G16: No | H16: =VLOOKUP(C16,Sheet2!A:D,3,0) -> Access | I16: =VLOOKUP(C16,Sheet2!A:D,4,0) -> No | J16: #N/A
A17: Cefalexin | B17: First-generation-cephalosporins | C17: J01DB01 | D17: Access | E17: Yes | F17: Access | G17: Yes | H17: =VLOOKUP(C17,Sheet2!A:D,3,0) -> Access | I17: =VLOOKUP(C17,Sheet2!A:D,4,0) -> Yes | J17: Access group antibiotics
A18: Cefaloridine | B18: First-generation-cephalosporins | C18: J01DB02 | D18: Access | E18: No | F18: Access | G18: No | H18: =VLOOKUP(C18,Sheet2!A:D,3,0) -> #N/A | I18: =VLOOKUP(C18,Sheet2!A:D,4,0) -> #N/A | J18: #N/A
A19: Cefalotin | B19: First-generation-cephalosporins | C19: J01DB03 | D19: Access | E19: No | F19: Access | G19: No | H19: =VLOOKUP(C19,Sheet2!A:D,3,0) -> Access | I19: =VLOOKUP(C19,Sheet2!A:D,4,0) -> No | J19: #N/A
A20: Cefapirin | B20: First-generation-cephalosporins | C20: J01DB08 | D20: Access | E20: No | F20: Access | G20: No | H20: =VLOOKUP(C20,Sheet2!A:D,3,0) -> Access | I20: =VLOOKUP(C20,Sheet2!A:D,4,0) -> No | J20: #N/A
A21: Cefatrizine | B21: First-generation-cephalosporins | C21: J01DB07 | D21: Access | E21: No | F21: Access | G21: No | H21: =VLOOKUP(C21,Sheet2!A:D,3,0) -> Access | I21: =VLOOKUP(C21,Sheet2!A:D,4,0) -> No | J21: #N/A
A22: Cefazedone | B22: First-generation-cephalosporins | C22: J01DB06 | D22: Access | E22: No | F22: Access | G22: No | H22: =VLOOKUP(C22,Sheet2!A:D,3,0) -> Access | I22: =VLOOKUP(C22,Sheet2!A:D,4,0) -> No | J22: #N/A
A23: Cefazolin | B23: First-generation-cephalosporins | C23: J01DB04 | D23: Access | E23: Yes | F23: Access | G23: Yes | H23: =VLOOKUP(C23,Sheet2!A:D,3,0) -> Access | I23: =VLOOKUP(C23,Sheet2!A:D,4,0) -> Yes | J23: Access group antibiotics
A24: Cefradine | B24: First-generation-cephalosporins | C24: J01DB09 | D24: Access | E24: No | F24: Access | G24: No | H24: =VLOOKUP(C24,Sheet2!A:D,3,0) -> Access | I24: =VLOOKUP(C24,Sheet2!A:D,4,0) -> No | J24: #N/A
A25: Cefroxadine | B25: First-generation-cephalosporins | C25: J01DB11 | D25: Access | E25: No | F25: Access | G25: No | H25: =VLOOKUP(C25,Sheet2!A:D,3,0) -> Access | I25: =VLOOKUP(C25,Sheet2!A:D,4,0) -> No | J25: #N/A
A26: Ceftezole | B26: First-generation-cephalosporins | C26: J01DB12 | D26: Access | E26: No | F26: Access | G26: No | H26: =VLOOKUP(C26,Sheet2!A:D,3,0) -> Access | I26: =VLOOKUP(C26,Sheet2!A:D,4,0) -> No | J26: #N/A
A27: Chloramphenicol | B27: Amphenicols | C27: J01BA01 | D27: Access | E27: Yes | F27: Access | G27: Yes | H27: =VLOOKUP(C27,Sheet2!A:D,3,0) -> Access | I27: =VLOOKUP(C27,Sheet2!A:D,4,0) -> Yes | J27: Access group antibiotics
A28: Clindamycin | B28: Lincosamides | C28: J01FF01 | D28: Access | E28: Yes | F28: Access | G28: Yes | H28: =VLOOKUP(C28,Sheet2!A:D,3,0) -> #N/A | I28: =VLOOKUP(C28,Sheet2!A:D,4,0) -> #N/A | J28: Access group antibiotics
A29: Clometocillin | B29: Penicillins | C29: J01CE07 | D29: Access | E29: No | F29: Access | G29: No | H29: =VLOOKUP(C29,Sheet2!A:D,3,0) -> Access | I29: =VLOOKUP(C29,Sheet2!A:D,4,0) -> No | J29: #N/A
A30: Cloxacillin | B30: Penicillins | C30: J01CF02 | D30: Access | E30: Yes | F30: Access | G30: Yes | H30: =VLOOKUP(C30,Sheet2!A:D,3,0) -> Access | I30: =VLOOKUP(C30,Sheet2!A:D,4,0) -> Yes | J30: Access group antibiotics
A31: Dicloxacillin | B31: Penicillins | C31: J01CF01 | D31: Access | E31: Yes | F31: Access | G31: No | H31: =VLOOKUP(C31,Sheet2!A:D,3,0) -> Access | I31: =VLOOKUP(C31,Sheet2!A:D,4,0) -> No | J31: #N/A
A32: Doxycycline | B32: Tetracyclines | C32: J01AA02 | D32: Access | E32: Yes | F32: Access | G32: Yes | H32: =VLOOKUP(C32,Sheet2!A:D,3,0) -> Access | I32: =VLOOKUP(C32,Sheet2!A:D,4,0) -> Yes | J32: Access group antibiotics
A33: Epicillin | B33: Penicillins | C33: J01CA07 | D33: Access | E33: No | F33: Access | G33: No | H33: =VLOOKUP(C33,Sheet2!A:D,3,0) -> #N/A | I33: =VLOOKUP(C33,Sheet2!A:D,4,0) -> #N/A | J33: #N/A
A34: Flucloxacillin | B34: Penicillins | C34: J01CF05 | D34: Access | E34: Yes | F34: Access | G34: No | H34: =VLOOKUP(C34,Sheet2!A:D,3,0) -> Access | I34: =VLOOKUP(C34,Sheet2!A:D,4,0) -> No | J34: #N/A
A35: Furazidin | B35: Nitrofuran-derivatives | C35: J01XE03 | D35: Access | E35: No | F35: Access | G35: No | H35: =VLOOKUP(C35,Sheet2!A:D,3,0) -> #N/A | I35: =VLOOKUP(C35,Sheet2!A:D,4,0) -> #N/A | J35: #N/A
A36: Gentamicin | B36: Aminoglycosides | C36: J01GB03 | D36: Access | E36: Yes | F36: Access | G36: Yes | H36: =VLOOKUP(C36,Sheet2!A:D,3,0) -> Access | I36: =VLOOKUP(C36,Sheet2!A:D,4,0) -> Yes | J36: Access group antibiotics
A37: Hetacillin | B37: Penicillins | C37: J01CA18 | D37: Access | E37: No | F37: Access | G37: No | H37: =VLOOKUP(C37,Sheet2!A:D,3,0) -> #N/A | I37: =VLOOKUP(C37,Sheet2!A:D,4,0) -> #N/A | J37: #N/A
A38: Mecillinam | B38: Penicillins | C38: J01CA11 | D38: Access | E38: No | F38: Access | G38: No | H38: =VLOOKUP(C38,Sheet2!A:D,3,0) -> Access | I38: =VLOOKUP(C38,Sheet2!A:D,4,0) -> No | J38: #N/A
A39: Metampicillin | B39: Penicillins | C39: J01CA14 | D39: Access | E39: No | F39: Access | G39: No | H39: =VLOOKUP(C39,Sheet2!A:D,3,0) -> #N/A | I39: =VLOOKUP(C39,Sheet2!A:D,4,0) -> #N/A | J39: #N/A
A40: Meticillin | B40: Penicillins | C40: J01CF03 | D40: Access | E40: Yes | F40: Access | G40: No | H40: =VLOOKUP(C40,Sheet2!A:D,3,0) -> #N/A | I40: =VLOOKUP(C40,Sheet2!A:D,4,0) -> #N/A | J40: #N/A
...

Sheet Sheet2
A1: ATC code | B1: Antibiotic | C1: Category | D1: Listed on EML 2019
A2: J01GB06 | B2: Amikacin | C2: Access | D2: Yes
A3: J01CA04 | B3: Amoxicillin | C3: Access | D3: Yes
A4: J01CR02 | B4: Amoxicillin/clavulanic Acid | C4: Access | D4: Yes
A5: J01CA01 | B5: Ampicillin | C5: Access | D5: Yes
A6: J01CR01 | B6: Ampicillin/sulbactam | C6: Access | D6: No
A7: J01GB12 | B7: Arbekacin | C7: Watch | D7: No
A8: J01FA10 | B8: Azithromycin | C8: Watch | D8: Yes
A9: J01CA09 | B9: Azlocillin | C9: Watch | D9: No
A10: J01DF01 | B10: Aztreonam | C10: Reserve | D10: No
A11: J01CA06 | B11: Bacampicillin | C11: Access | D11: No
A12: J01CE08 | B12: Benzathine benzylpenicillin | C12: Access | D12: Yes
... A181: A07AA09 | B181: Vancomycin (oral) | C181: Watch | D181: Yes
